{
 "cells": [
  {
   "cell_type": "markdown",
   "id": "bff574fd",
   "metadata": {},
   "source": [
    "### Import liberaries"
   ]
  },
  {
   "cell_type": "code",
   "execution_count": 16,
   "id": "ceb20064",
   "metadata": {},
   "outputs": [],
   "source": [
    "from keras.models import Sequential\n",
    "from keras.layers import Conv2D, MaxPooling2D, Dense, Dropout, Flatten\n",
    "from keras.optimizers import Adam\n",
    "from keras.preprocessing.image import ImageDataGenerator\n",
    "import tensorflow as tf"
   ]
  },
  {
   "cell_type": "markdown",
   "id": "3d6672e8",
   "metadata": {},
   "source": [
    "## Initialize image data genertaor with rescaling"
   ]
  },
  {
   "cell_type": "code",
   "execution_count": 6,
   "id": "479025e5",
   "metadata": {},
   "outputs": [],
   "source": [
    "# Image preproceesing (rescale / Normalization)\n",
    "train_data_gen = ImageDataGenerator(rescale = 1/255)\n",
    "\n",
    "validation_data_gen = ImageDataGenerator(rescale = 1/255)"
   ]
  },
  {
   "cell_type": "markdown",
   "id": "1a433dbe",
   "metadata": {},
   "source": [
    "### Process all train images"
   ]
  },
  {
   "cell_type": "code",
   "execution_count": 8,
   "id": "745430c4",
   "metadata": {},
   "outputs": [
    {
     "name": "stdout",
     "output_type": "stream",
     "text": [
      "Found 28709 images belonging to 7 classes.\n"
     ]
    }
   ],
   "source": [
    "# collect all the data and preprocess them\n",
    "train_generator = train_data_gen.flow_from_directory(\n",
    "        \"dataset/train\",\n",
    "        target_size = (48,48),\n",
    "        batch_size = 64,\n",
    "        color_mode = \"grayscale\",\n",
    "        class_mode = \"categorical\")"
   ]
  },
  {
   "cell_type": "markdown",
   "id": "38fd8450",
   "metadata": {},
   "source": [
    "**Process all test images**"
   ]
  },
  {
   "cell_type": "code",
   "execution_count": 10,
   "id": "a78e2f9a",
   "metadata": {},
   "outputs": [
    {
     "name": "stdout",
     "output_type": "stream",
     "text": [
      "Found 7178 images belonging to 7 classes.\n"
     ]
    }
   ],
   "source": [
    "validation_generator = validation_data_gen.flow_from_directory(\n",
    "        \"dataset/test\",\n",
    "        batch_size = 64,\n",
    "        color_mode = \"grayscale\",\n",
    "        class_mode = \"categorical\")"
   ]
  },
  {
   "cell_type": "markdown",
   "id": "cba77fe9",
   "metadata": {},
   "source": [
    "### Building the model"
   ]
  },
  {
   "cell_type": "code",
   "execution_count": 11,
   "id": "ac53b490",
   "metadata": {},
   "outputs": [
    {
     "name": "stdout",
     "output_type": "stream",
     "text": [
      "WARNING:tensorflow:From C:\\Users\\Administrator\\anaconda3\\lib\\site-packages\\keras\\src\\backend.py:873: The name tf.get_default_graph is deprecated. Please use tf.compat.v1.get_default_graph instead.\n",
      "\n",
      "WARNING:tensorflow:From C:\\Users\\Administrator\\anaconda3\\lib\\site-packages\\keras\\src\\layers\\pooling\\max_pooling2d.py:161: The name tf.nn.max_pool is deprecated. Please use tf.nn.max_pool2d instead.\n",
      "\n"
     ]
    }
   ],
   "source": [
    "emotion_model = Sequential()\n",
    "\n",
    "emotion_model.add(Conv2D(32, kernel_size =(3,3), activation = \"relu\",input_shape =(48,48,1))) \n",
    "emotion_model.add(Conv2D(64 , kernel_size =(3,3), activation = 'relu'))\n",
    "emotion_model.add(MaxPooling2D(pool_size = (2,2)))\n",
    "emotion_model.add(Dropout(0.25)) # avoid overfitting\n",
    "\n",
    "emotion_model.add(Conv2D(128 , kernel_size = (3,3) , activation = \"relu\"))\n",
    "emotion_model.add(MaxPooling2D(pool_size = (2,2)))\n",
    "emotion_model.add(Conv2D(128, kernel_size = (3,3), activation = \"relu\"))\n",
    "emotion_model.add(MaxPooling2D(pool_size = (2,2)))\n",
    "emotion_model.add(Dropout(0.25))\n",
    "\n",
    "emotion_model.add(Flatten())\n",
    "emotion_model.add(Dense(1024 , activation = \"relu\"))\n",
    "emotion_model.add(Dropout(0.5))\n",
    "emotion_model.add(Dense(7 , activation = \"softmax\")) # 7 : \"7 categories\""
   ]
  },
  {
   "cell_type": "markdown",
   "id": "465e5dc0",
   "metadata": {},
   "source": [
    "### Compiling the Model "
   ]
  },
  {
   "cell_type": "code",
   "execution_count": 17,
   "id": "3fb15dde",
   "metadata": {},
   "outputs": [
    {
     "name": "stderr",
     "output_type": "stream",
     "text": [
      "C:\\Users\\Administrator\\anaconda3\\lib\\site-packages\\keras\\src\\optimizers\\legacy\\adam.py:118: UserWarning: The `lr` argument is deprecated, use `learning_rate` instead.\n",
      "  super().__init__(name, **kwargs)\n"
     ]
    }
   ],
   "source": [
    "emotion_model.compile(loss = \"categorical_crossentropy\", \n",
    "                      optimizer = tf.keras.optimizers.legacy.Adam(lr = 0.0001 , decay = 1e-6),\n",
    "                      metrics = [\"accuracy\"])"
   ]
  },
  {
   "cell_type": "markdown",
   "id": "4f0fbaf0",
   "metadata": {},
   "source": [
    "### Trainning the model"
   ]
  },
  {
   "cell_type": "code",
   "execution_count": 18,
   "id": "85b07146",
   "metadata": {},
   "outputs": [
    {
     "name": "stderr",
     "output_type": "stream",
     "text": [
      "C:\\Users\\Administrator\\AppData\\Local\\Temp\\ipykernel_6016\\126627924.py:1: UserWarning: `Model.fit_generator` is deprecated and will be removed in a future version. Please use `Model.fit`, which supports generators.\n",
      "  emotion_model_info = emotion_model.fit_generator(\n"
     ]
    },
    {
     "name": "stdout",
     "output_type": "stream",
     "text": [
      "Epoch 1/20\n",
      "WARNING:tensorflow:From C:\\Users\\Administrator\\anaconda3\\lib\\site-packages\\keras\\src\\utils\\tf_utils.py:492: The name tf.ragged.RaggedTensorValue is deprecated. Please use tf.compat.v1.ragged.RaggedTensorValue instead.\n",
      "\n"
     ]
    },
    {
     "name": "stderr",
     "output_type": "stream",
     "text": [
      "WARNING:tensorflow:From C:\\Users\\Administrator\\anaconda3\\lib\\site-packages\\keras\\src\\utils\\tf_utils.py:492: The name tf.ragged.RaggedTensorValue is deprecated. Please use tf.compat.v1.ragged.RaggedTensorValue instead.\n",
      "\n"
     ]
    },
    {
     "name": "stdout",
     "output_type": "stream",
     "text": [
      "WARNING:tensorflow:From C:\\Users\\Administrator\\anaconda3\\lib\\site-packages\\keras\\src\\engine\\base_layer_utils.py:384: The name tf.executing_eagerly_outside_functions is deprecated. Please use tf.compat.v1.executing_eagerly_outside_functions instead.\n",
      "\n"
     ]
    },
    {
     "name": "stderr",
     "output_type": "stream",
     "text": [
      "WARNING:tensorflow:From C:\\Users\\Administrator\\anaconda3\\lib\\site-packages\\keras\\src\\engine\\base_layer_utils.py:384: The name tf.executing_eagerly_outside_functions is deprecated. Please use tf.compat.v1.executing_eagerly_outside_functions instead.\n",
      "\n"
     ]
    },
    {
     "name": "stdout",
     "output_type": "stream",
     "text": [
      "448/448 [==============================] - ETA: 0s - loss: 1.8019 - accuracy: 0.2610"
     ]
    },
    {
     "ename": "InvalidArgumentError",
     "evalue": "Graph execution error:\n\nDetected at node sequential/dense/Relu defined at (most recent call last):\n  File \"C:\\Users\\Administrator\\anaconda3\\lib\\runpy.py\", line 196, in _run_module_as_main\n\n  File \"C:\\Users\\Administrator\\anaconda3\\lib\\runpy.py\", line 86, in _run_code\n\n  File \"C:\\Users\\Administrator\\anaconda3\\lib\\site-packages\\ipykernel_launcher.py\", line 17, in <module>\n\n  File \"C:\\Users\\Administrator\\anaconda3\\lib\\site-packages\\traitlets\\config\\application.py\", line 992, in launch_instance\n\n  File \"C:\\Users\\Administrator\\anaconda3\\lib\\site-packages\\ipykernel\\kernelapp.py\", line 711, in start\n\n  File \"C:\\Users\\Administrator\\anaconda3\\lib\\site-packages\\tornado\\platform\\asyncio.py\", line 199, in start\n\n  File \"C:\\Users\\Administrator\\anaconda3\\lib\\asyncio\\base_events.py\", line 603, in run_forever\n\n  File \"C:\\Users\\Administrator\\anaconda3\\lib\\asyncio\\base_events.py\", line 1906, in _run_once\n\n  File \"C:\\Users\\Administrator\\anaconda3\\lib\\asyncio\\events.py\", line 80, in _run\n\n  File \"C:\\Users\\Administrator\\anaconda3\\lib\\site-packages\\ipykernel\\kernelbase.py\", line 510, in dispatch_queue\n\n  File \"C:\\Users\\Administrator\\anaconda3\\lib\\site-packages\\ipykernel\\kernelbase.py\", line 499, in process_one\n\n  File \"C:\\Users\\Administrator\\anaconda3\\lib\\site-packages\\ipykernel\\kernelbase.py\", line 406, in dispatch_shell\n\n  File \"C:\\Users\\Administrator\\anaconda3\\lib\\site-packages\\ipykernel\\kernelbase.py\", line 729, in execute_request\n\n  File \"C:\\Users\\Administrator\\anaconda3\\lib\\site-packages\\ipykernel\\ipkernel.py\", line 411, in do_execute\n\n  File \"C:\\Users\\Administrator\\anaconda3\\lib\\site-packages\\ipykernel\\zmqshell.py\", line 531, in run_cell\n\n  File \"C:\\Users\\Administrator\\anaconda3\\lib\\site-packages\\IPython\\core\\interactiveshell.py\", line 2961, in run_cell\n\n  File \"C:\\Users\\Administrator\\anaconda3\\lib\\site-packages\\IPython\\core\\interactiveshell.py\", line 3016, in _run_cell\n\n  File \"C:\\Users\\Administrator\\anaconda3\\lib\\site-packages\\IPython\\core\\async_helpers.py\", line 129, in _pseudo_sync_runner\n\n  File \"C:\\Users\\Administrator\\anaconda3\\lib\\site-packages\\IPython\\core\\interactiveshell.py\", line 3221, in run_cell_async\n\n  File \"C:\\Users\\Administrator\\anaconda3\\lib\\site-packages\\IPython\\core\\interactiveshell.py\", line 3400, in run_ast_nodes\n\n  File \"C:\\Users\\Administrator\\anaconda3\\lib\\site-packages\\IPython\\core\\interactiveshell.py\", line 3460, in run_code\n\n  File \"C:\\Users\\Administrator\\AppData\\Local\\Temp\\ipykernel_6016\\126627924.py\", line 1, in <module>\n\n  File \"C:\\Users\\Administrator\\anaconda3\\lib\\site-packages\\keras\\src\\engine\\training.py\", line 2913, in fit_generator\n\n  File \"C:\\Users\\Administrator\\anaconda3\\lib\\site-packages\\keras\\src\\utils\\traceback_utils.py\", line 65, in error_handler\n\n  File \"C:\\Users\\Administrator\\anaconda3\\lib\\site-packages\\keras\\src\\engine\\training.py\", line 1856, in fit\n\n  File \"C:\\Users\\Administrator\\anaconda3\\lib\\site-packages\\keras\\src\\utils\\traceback_utils.py\", line 65, in error_handler\n\n  File \"C:\\Users\\Administrator\\anaconda3\\lib\\site-packages\\keras\\src\\engine\\training.py\", line 2296, in evaluate\n\n  File \"C:\\Users\\Administrator\\anaconda3\\lib\\site-packages\\keras\\src\\engine\\training.py\", line 4108, in run_step\n\n  File \"C:\\Users\\Administrator\\anaconda3\\lib\\site-packages\\keras\\src\\engine\\training.py\", line 2066, in test_function\n\n  File \"C:\\Users\\Administrator\\anaconda3\\lib\\site-packages\\keras\\src\\engine\\training.py\", line 2049, in step_function\n\n  File \"C:\\Users\\Administrator\\anaconda3\\lib\\site-packages\\keras\\src\\engine\\training.py\", line 2037, in run_step\n\n  File \"C:\\Users\\Administrator\\anaconda3\\lib\\site-packages\\keras\\src\\engine\\training.py\", line 1917, in test_step\n\n  File \"C:\\Users\\Administrator\\anaconda3\\lib\\site-packages\\keras\\src\\utils\\traceback_utils.py\", line 65, in error_handler\n\n  File \"C:\\Users\\Administrator\\anaconda3\\lib\\site-packages\\keras\\src\\engine\\training.py\", line 590, in __call__\n\n  File \"C:\\Users\\Administrator\\anaconda3\\lib\\site-packages\\keras\\src\\utils\\traceback_utils.py\", line 65, in error_handler\n\n  File \"C:\\Users\\Administrator\\anaconda3\\lib\\site-packages\\keras\\src\\engine\\base_layer.py\", line 1149, in __call__\n\n  File \"C:\\Users\\Administrator\\anaconda3\\lib\\site-packages\\keras\\src\\utils\\traceback_utils.py\", line 96, in error_handler\n\n  File \"C:\\Users\\Administrator\\anaconda3\\lib\\site-packages\\keras\\src\\engine\\sequential.py\", line 398, in call\n\n  File \"C:\\Users\\Administrator\\anaconda3\\lib\\site-packages\\keras\\src\\engine\\functional.py\", line 515, in call\n\n  File \"C:\\Users\\Administrator\\anaconda3\\lib\\site-packages\\keras\\src\\engine\\functional.py\", line 672, in _run_internal_graph\n\n  File \"C:\\Users\\Administrator\\anaconda3\\lib\\site-packages\\keras\\src\\utils\\traceback_utils.py\", line 65, in error_handler\n\n  File \"C:\\Users\\Administrator\\anaconda3\\lib\\site-packages\\keras\\src\\engine\\base_layer.py\", line 1149, in __call__\n\n  File \"C:\\Users\\Administrator\\anaconda3\\lib\\site-packages\\keras\\src\\utils\\traceback_utils.py\", line 96, in error_handler\n\n  File \"C:\\Users\\Administrator\\anaconda3\\lib\\site-packages\\keras\\src\\layers\\core\\dense.py\", line 255, in call\n\n  File \"C:\\Users\\Administrator\\anaconda3\\lib\\site-packages\\keras\\src\\activations.py\", line 306, in relu\n\n  File \"C:\\Users\\Administrator\\anaconda3\\lib\\site-packages\\keras\\src\\backend.py\", line 5395, in relu\n\nMatrix size-incompatible: In[0]: [64,115200], In[1]: [2048,1024]\n\t [[{{node sequential/dense/Relu}}]] [Op:__inference_test_function_3183]",
     "output_type": "error",
     "traceback": [
      "\u001b[1;31m---------------------------------------------------------------------------\u001b[0m",
      "\u001b[1;31mInvalidArgumentError\u001b[0m                      Traceback (most recent call last)",
      "Cell \u001b[1;32mIn[18], line 1\u001b[0m\n\u001b[1;32m----> 1\u001b[0m emotion_model_info \u001b[38;5;241m=\u001b[39m \u001b[43memotion_model\u001b[49m\u001b[38;5;241;43m.\u001b[39;49m\u001b[43mfit_generator\u001b[49m\u001b[43m(\u001b[49m\n\u001b[0;32m      2\u001b[0m \u001b[43m            \u001b[49m\u001b[43mtrain_generator\u001b[49m\u001b[43m,\u001b[49m\n\u001b[0;32m      3\u001b[0m \u001b[43m            \u001b[49m\u001b[43msteps_per_epoch\u001b[49m\u001b[43m \u001b[49m\u001b[38;5;241;43m=\u001b[39;49m\u001b[43m \u001b[49m\u001b[38;5;241;43m28709\u001b[39;49m\u001b[43m \u001b[49m\u001b[38;5;241;43m/\u001b[39;49m\u001b[38;5;241;43m/\u001b[39;49m\u001b[43m \u001b[49m\u001b[38;5;241;43m64\u001b[39;49m\u001b[43m,\u001b[49m\n\u001b[0;32m      4\u001b[0m \u001b[43m            \u001b[49m\u001b[43mepochs\u001b[49m\u001b[43m \u001b[49m\u001b[38;5;241;43m=\u001b[39;49m\u001b[43m \u001b[49m\u001b[38;5;241;43m20\u001b[39;49m\u001b[43m \u001b[49m\u001b[43m,\u001b[49m\u001b[43m \u001b[49m\n\u001b[0;32m      5\u001b[0m \u001b[43m            \u001b[49m\u001b[43mvalidation_data\u001b[49m\u001b[43m \u001b[49m\u001b[38;5;241;43m=\u001b[39;49m\u001b[43m \u001b[49m\u001b[43mvalidation_generator\u001b[49m\u001b[43m,\u001b[49m\n\u001b[0;32m      6\u001b[0m \u001b[43m            \u001b[49m\u001b[43mvalidation_steps\u001b[49m\u001b[43m \u001b[49m\u001b[38;5;241;43m=\u001b[39;49m\u001b[43m \u001b[49m\u001b[38;5;241;43m7178\u001b[39;49m\u001b[43m \u001b[49m\u001b[38;5;241;43m/\u001b[39;49m\u001b[38;5;241;43m/\u001b[39;49m\u001b[43m \u001b[49m\u001b[38;5;241;43m64\u001b[39;49m\u001b[43m)\u001b[49m\n",
      "File \u001b[1;32m~\\anaconda3\\lib\\site-packages\\keras\\src\\engine\\training.py:2913\u001b[0m, in \u001b[0;36mModel.fit_generator\u001b[1;34m(self, generator, steps_per_epoch, epochs, verbose, callbacks, validation_data, validation_steps, validation_freq, class_weight, max_queue_size, workers, use_multiprocessing, shuffle, initial_epoch)\u001b[0m\n\u001b[0;32m   2901\u001b[0m \u001b[38;5;124;03m\"\"\"Fits the model on data yielded batch-by-batch by a Python generator.\u001b[39;00m\n\u001b[0;32m   2902\u001b[0m \n\u001b[0;32m   2903\u001b[0m \u001b[38;5;124;03mDEPRECATED:\u001b[39;00m\n\u001b[0;32m   2904\u001b[0m \u001b[38;5;124;03m  `Model.fit` now supports generators, so there is no longer any need to\u001b[39;00m\n\u001b[0;32m   2905\u001b[0m \u001b[38;5;124;03m  use this endpoint.\u001b[39;00m\n\u001b[0;32m   2906\u001b[0m \u001b[38;5;124;03m\"\"\"\u001b[39;00m\n\u001b[0;32m   2907\u001b[0m warnings\u001b[38;5;241m.\u001b[39mwarn(\n\u001b[0;32m   2908\u001b[0m     \u001b[38;5;124m\"\u001b[39m\u001b[38;5;124m`Model.fit_generator` is deprecated and \u001b[39m\u001b[38;5;124m\"\u001b[39m\n\u001b[0;32m   2909\u001b[0m     \u001b[38;5;124m\"\u001b[39m\u001b[38;5;124mwill be removed in a future version. \u001b[39m\u001b[38;5;124m\"\u001b[39m\n\u001b[0;32m   2910\u001b[0m     \u001b[38;5;124m\"\u001b[39m\u001b[38;5;124mPlease use `Model.fit`, which supports generators.\u001b[39m\u001b[38;5;124m\"\u001b[39m,\n\u001b[0;32m   2911\u001b[0m     stacklevel\u001b[38;5;241m=\u001b[39m\u001b[38;5;241m2\u001b[39m,\n\u001b[0;32m   2912\u001b[0m )\n\u001b[1;32m-> 2913\u001b[0m \u001b[38;5;28;01mreturn\u001b[39;00m \u001b[38;5;28;43mself\u001b[39;49m\u001b[38;5;241;43m.\u001b[39;49m\u001b[43mfit\u001b[49m\u001b[43m(\u001b[49m\n\u001b[0;32m   2914\u001b[0m \u001b[43m    \u001b[49m\u001b[43mgenerator\u001b[49m\u001b[43m,\u001b[49m\n\u001b[0;32m   2915\u001b[0m \u001b[43m    \u001b[49m\u001b[43msteps_per_epoch\u001b[49m\u001b[38;5;241;43m=\u001b[39;49m\u001b[43msteps_per_epoch\u001b[49m\u001b[43m,\u001b[49m\n\u001b[0;32m   2916\u001b[0m \u001b[43m    \u001b[49m\u001b[43mepochs\u001b[49m\u001b[38;5;241;43m=\u001b[39;49m\u001b[43mepochs\u001b[49m\u001b[43m,\u001b[49m\n\u001b[0;32m   2917\u001b[0m \u001b[43m    \u001b[49m\u001b[43mverbose\u001b[49m\u001b[38;5;241;43m=\u001b[39;49m\u001b[43mverbose\u001b[49m\u001b[43m,\u001b[49m\n\u001b[0;32m   2918\u001b[0m \u001b[43m    \u001b[49m\u001b[43mcallbacks\u001b[49m\u001b[38;5;241;43m=\u001b[39;49m\u001b[43mcallbacks\u001b[49m\u001b[43m,\u001b[49m\n\u001b[0;32m   2919\u001b[0m \u001b[43m    \u001b[49m\u001b[43mvalidation_data\u001b[49m\u001b[38;5;241;43m=\u001b[39;49m\u001b[43mvalidation_data\u001b[49m\u001b[43m,\u001b[49m\n\u001b[0;32m   2920\u001b[0m \u001b[43m    \u001b[49m\u001b[43mvalidation_steps\u001b[49m\u001b[38;5;241;43m=\u001b[39;49m\u001b[43mvalidation_steps\u001b[49m\u001b[43m,\u001b[49m\n\u001b[0;32m   2921\u001b[0m \u001b[43m    \u001b[49m\u001b[43mvalidation_freq\u001b[49m\u001b[38;5;241;43m=\u001b[39;49m\u001b[43mvalidation_freq\u001b[49m\u001b[43m,\u001b[49m\n\u001b[0;32m   2922\u001b[0m \u001b[43m    \u001b[49m\u001b[43mclass_weight\u001b[49m\u001b[38;5;241;43m=\u001b[39;49m\u001b[43mclass_weight\u001b[49m\u001b[43m,\u001b[49m\n\u001b[0;32m   2923\u001b[0m \u001b[43m    \u001b[49m\u001b[43mmax_queue_size\u001b[49m\u001b[38;5;241;43m=\u001b[39;49m\u001b[43mmax_queue_size\u001b[49m\u001b[43m,\u001b[49m\n\u001b[0;32m   2924\u001b[0m \u001b[43m    \u001b[49m\u001b[43mworkers\u001b[49m\u001b[38;5;241;43m=\u001b[39;49m\u001b[43mworkers\u001b[49m\u001b[43m,\u001b[49m\n\u001b[0;32m   2925\u001b[0m \u001b[43m    \u001b[49m\u001b[43muse_multiprocessing\u001b[49m\u001b[38;5;241;43m=\u001b[39;49m\u001b[43muse_multiprocessing\u001b[49m\u001b[43m,\u001b[49m\n\u001b[0;32m   2926\u001b[0m \u001b[43m    \u001b[49m\u001b[43mshuffle\u001b[49m\u001b[38;5;241;43m=\u001b[39;49m\u001b[43mshuffle\u001b[49m\u001b[43m,\u001b[49m\n\u001b[0;32m   2927\u001b[0m \u001b[43m    \u001b[49m\u001b[43minitial_epoch\u001b[49m\u001b[38;5;241;43m=\u001b[39;49m\u001b[43minitial_epoch\u001b[49m\u001b[43m,\u001b[49m\n\u001b[0;32m   2928\u001b[0m \u001b[43m\u001b[49m\u001b[43m)\u001b[49m\n",
      "File \u001b[1;32m~\\anaconda3\\lib\\site-packages\\keras\\src\\utils\\traceback_utils.py:70\u001b[0m, in \u001b[0;36mfilter_traceback.<locals>.error_handler\u001b[1;34m(*args, **kwargs)\u001b[0m\n\u001b[0;32m     67\u001b[0m     filtered_tb \u001b[38;5;241m=\u001b[39m _process_traceback_frames(e\u001b[38;5;241m.\u001b[39m__traceback__)\n\u001b[0;32m     68\u001b[0m     \u001b[38;5;66;03m# To get the full stack trace, call:\u001b[39;00m\n\u001b[0;32m     69\u001b[0m     \u001b[38;5;66;03m# `tf.debugging.disable_traceback_filtering()`\u001b[39;00m\n\u001b[1;32m---> 70\u001b[0m     \u001b[38;5;28;01mraise\u001b[39;00m e\u001b[38;5;241m.\u001b[39mwith_traceback(filtered_tb) \u001b[38;5;28;01mfrom\u001b[39;00m \u001b[38;5;28mNone\u001b[39m\n\u001b[0;32m     71\u001b[0m \u001b[38;5;28;01mfinally\u001b[39;00m:\n\u001b[0;32m     72\u001b[0m     \u001b[38;5;28;01mdel\u001b[39;00m filtered_tb\n",
      "File \u001b[1;32m~\\anaconda3\\lib\\site-packages\\tensorflow\\python\\eager\\execute.py:53\u001b[0m, in \u001b[0;36mquick_execute\u001b[1;34m(op_name, num_outputs, inputs, attrs, ctx, name)\u001b[0m\n\u001b[0;32m     51\u001b[0m \u001b[38;5;28;01mtry\u001b[39;00m:\n\u001b[0;32m     52\u001b[0m   ctx\u001b[38;5;241m.\u001b[39mensure_initialized()\n\u001b[1;32m---> 53\u001b[0m   tensors \u001b[38;5;241m=\u001b[39m pywrap_tfe\u001b[38;5;241m.\u001b[39mTFE_Py_Execute(ctx\u001b[38;5;241m.\u001b[39m_handle, device_name, op_name,\n\u001b[0;32m     54\u001b[0m                                       inputs, attrs, num_outputs)\n\u001b[0;32m     55\u001b[0m \u001b[38;5;28;01mexcept\u001b[39;00m core\u001b[38;5;241m.\u001b[39m_NotOkStatusException \u001b[38;5;28;01mas\u001b[39;00m e:\n\u001b[0;32m     56\u001b[0m   \u001b[38;5;28;01mif\u001b[39;00m name \u001b[38;5;129;01mis\u001b[39;00m \u001b[38;5;129;01mnot\u001b[39;00m \u001b[38;5;28;01mNone\u001b[39;00m:\n",
      "\u001b[1;31mInvalidArgumentError\u001b[0m: Graph execution error:\n\nDetected at node sequential/dense/Relu defined at (most recent call last):\n  File \"C:\\Users\\Administrator\\anaconda3\\lib\\runpy.py\", line 196, in _run_module_as_main\n\n  File \"C:\\Users\\Administrator\\anaconda3\\lib\\runpy.py\", line 86, in _run_code\n\n  File \"C:\\Users\\Administrator\\anaconda3\\lib\\site-packages\\ipykernel_launcher.py\", line 17, in <module>\n\n  File \"C:\\Users\\Administrator\\anaconda3\\lib\\site-packages\\traitlets\\config\\application.py\", line 992, in launch_instance\n\n  File \"C:\\Users\\Administrator\\anaconda3\\lib\\site-packages\\ipykernel\\kernelapp.py\", line 711, in start\n\n  File \"C:\\Users\\Administrator\\anaconda3\\lib\\site-packages\\tornado\\platform\\asyncio.py\", line 199, in start\n\n  File \"C:\\Users\\Administrator\\anaconda3\\lib\\asyncio\\base_events.py\", line 603, in run_forever\n\n  File \"C:\\Users\\Administrator\\anaconda3\\lib\\asyncio\\base_events.py\", line 1906, in _run_once\n\n  File \"C:\\Users\\Administrator\\anaconda3\\lib\\asyncio\\events.py\", line 80, in _run\n\n  File \"C:\\Users\\Administrator\\anaconda3\\lib\\site-packages\\ipykernel\\kernelbase.py\", line 510, in dispatch_queue\n\n  File \"C:\\Users\\Administrator\\anaconda3\\lib\\site-packages\\ipykernel\\kernelbase.py\", line 499, in process_one\n\n  File \"C:\\Users\\Administrator\\anaconda3\\lib\\site-packages\\ipykernel\\kernelbase.py\", line 406, in dispatch_shell\n\n  File \"C:\\Users\\Administrator\\anaconda3\\lib\\site-packages\\ipykernel\\kernelbase.py\", line 729, in execute_request\n\n  File \"C:\\Users\\Administrator\\anaconda3\\lib\\site-packages\\ipykernel\\ipkernel.py\", line 411, in do_execute\n\n  File \"C:\\Users\\Administrator\\anaconda3\\lib\\site-packages\\ipykernel\\zmqshell.py\", line 531, in run_cell\n\n  File \"C:\\Users\\Administrator\\anaconda3\\lib\\site-packages\\IPython\\core\\interactiveshell.py\", line 2961, in run_cell\n\n  File \"C:\\Users\\Administrator\\anaconda3\\lib\\site-packages\\IPython\\core\\interactiveshell.py\", line 3016, in _run_cell\n\n  File \"C:\\Users\\Administrator\\anaconda3\\lib\\site-packages\\IPython\\core\\async_helpers.py\", line 129, in _pseudo_sync_runner\n\n  File \"C:\\Users\\Administrator\\anaconda3\\lib\\site-packages\\IPython\\core\\interactiveshell.py\", line 3221, in run_cell_async\n\n  File \"C:\\Users\\Administrator\\anaconda3\\lib\\site-packages\\IPython\\core\\interactiveshell.py\", line 3400, in run_ast_nodes\n\n  File \"C:\\Users\\Administrator\\anaconda3\\lib\\site-packages\\IPython\\core\\interactiveshell.py\", line 3460, in run_code\n\n  File \"C:\\Users\\Administrator\\AppData\\Local\\Temp\\ipykernel_6016\\126627924.py\", line 1, in <module>\n\n  File \"C:\\Users\\Administrator\\anaconda3\\lib\\site-packages\\keras\\src\\engine\\training.py\", line 2913, in fit_generator\n\n  File \"C:\\Users\\Administrator\\anaconda3\\lib\\site-packages\\keras\\src\\utils\\traceback_utils.py\", line 65, in error_handler\n\n  File \"C:\\Users\\Administrator\\anaconda3\\lib\\site-packages\\keras\\src\\engine\\training.py\", line 1856, in fit\n\n  File \"C:\\Users\\Administrator\\anaconda3\\lib\\site-packages\\keras\\src\\utils\\traceback_utils.py\", line 65, in error_handler\n\n  File \"C:\\Users\\Administrator\\anaconda3\\lib\\site-packages\\keras\\src\\engine\\training.py\", line 2296, in evaluate\n\n  File \"C:\\Users\\Administrator\\anaconda3\\lib\\site-packages\\keras\\src\\engine\\training.py\", line 4108, in run_step\n\n  File \"C:\\Users\\Administrator\\anaconda3\\lib\\site-packages\\keras\\src\\engine\\training.py\", line 2066, in test_function\n\n  File \"C:\\Users\\Administrator\\anaconda3\\lib\\site-packages\\keras\\src\\engine\\training.py\", line 2049, in step_function\n\n  File \"C:\\Users\\Administrator\\anaconda3\\lib\\site-packages\\keras\\src\\engine\\training.py\", line 2037, in run_step\n\n  File \"C:\\Users\\Administrator\\anaconda3\\lib\\site-packages\\keras\\src\\engine\\training.py\", line 1917, in test_step\n\n  File \"C:\\Users\\Administrator\\anaconda3\\lib\\site-packages\\keras\\src\\utils\\traceback_utils.py\", line 65, in error_handler\n\n  File \"C:\\Users\\Administrator\\anaconda3\\lib\\site-packages\\keras\\src\\engine\\training.py\", line 590, in __call__\n\n  File \"C:\\Users\\Administrator\\anaconda3\\lib\\site-packages\\keras\\src\\utils\\traceback_utils.py\", line 65, in error_handler\n\n  File \"C:\\Users\\Administrator\\anaconda3\\lib\\site-packages\\keras\\src\\engine\\base_layer.py\", line 1149, in __call__\n\n  File \"C:\\Users\\Administrator\\anaconda3\\lib\\site-packages\\keras\\src\\utils\\traceback_utils.py\", line 96, in error_handler\n\n  File \"C:\\Users\\Administrator\\anaconda3\\lib\\site-packages\\keras\\src\\engine\\sequential.py\", line 398, in call\n\n  File \"C:\\Users\\Administrator\\anaconda3\\lib\\site-packages\\keras\\src\\engine\\functional.py\", line 515, in call\n\n  File \"C:\\Users\\Administrator\\anaconda3\\lib\\site-packages\\keras\\src\\engine\\functional.py\", line 672, in _run_internal_graph\n\n  File \"C:\\Users\\Administrator\\anaconda3\\lib\\site-packages\\keras\\src\\utils\\traceback_utils.py\", line 65, in error_handler\n\n  File \"C:\\Users\\Administrator\\anaconda3\\lib\\site-packages\\keras\\src\\engine\\base_layer.py\", line 1149, in __call__\n\n  File \"C:\\Users\\Administrator\\anaconda3\\lib\\site-packages\\keras\\src\\utils\\traceback_utils.py\", line 96, in error_handler\n\n  File \"C:\\Users\\Administrator\\anaconda3\\lib\\site-packages\\keras\\src\\layers\\core\\dense.py\", line 255, in call\n\n  File \"C:\\Users\\Administrator\\anaconda3\\lib\\site-packages\\keras\\src\\activations.py\", line 306, in relu\n\n  File \"C:\\Users\\Administrator\\anaconda3\\lib\\site-packages\\keras\\src\\backend.py\", line 5395, in relu\n\nMatrix size-incompatible: In[0]: [64,115200], In[1]: [2048,1024]\n\t [[{{node sequential/dense/Relu}}]] [Op:__inference_test_function_3183]"
     ]
    }
   ],
   "source": [
    "emotion_model_info = emotion_model.fit_generator(\n",
    "            train_generator,\n",
    "            steps_per_epoch = 28709 // 64,\n",
    "            epochs = 20 , \n",
    "            validation_data = validation_generator,\n",
    "            validation_steps = 7178 // 64)"
   ]
  },
  {
   "cell_type": "markdown",
   "id": "94d674e4",
   "metadata": {},
   "source": [
    "**Save the model structure in jason file**"
   ]
  },
  {
   "cell_type": "code",
   "execution_count": null,
   "id": "76811570",
   "metadata": {},
   "outputs": [],
   "source": [
    "model_json = emotion_detection.to_json()\n",
    "with open(\"emotion_model.json\" , \"w\") as jason_file:\n",
    "    json_file.write(model_json)"
   ]
  },
  {
   "cell_type": "markdown",
   "id": "5073f7e2",
   "metadata": {},
   "source": [
    "**Save trained model weight in h5 file**"
   ]
  },
  {
   "cell_type": "code",
   "execution_count": null,
   "id": "e2437205",
   "metadata": {},
   "outputs": [],
   "source": [
    "emotion_model.save_weights(\"emotion_model.h5\")"
   ]
  }
 ],
 "metadata": {
  "kernelspec": {
   "display_name": "Python 3 (ipykernel)",
   "language": "python",
   "name": "python3"
  },
  "language_info": {
   "codemirror_mode": {
    "name": "ipython",
    "version": 3
   },
   "file_extension": ".py",
   "mimetype": "text/x-python",
   "name": "python",
   "nbconvert_exporter": "python",
   "pygments_lexer": "ipython3",
   "version": "3.10.9"
  }
 },
 "nbformat": 4,
 "nbformat_minor": 5
}
